<?xml version='1.0'?>
<sdf version='1.7'>
  <model name='robot'>
    <link name='link'>
      <pose>0 0 0 0 3.14 3.14</pose>
      <inertial>
        <mass>1</mass>
        <inertia>
          <ixx>0.166667</ixx>
          <ixy>0</ixy>
          <ixz>0</ixz>
          <iyy>0.166667</iyy>
          <iyz>0</iyz>
          <izz>0.166667</izz>
        </inertia>
        <pose>0 0 0 0 -0 0</pose>
      </inertial>
      <gravity>1</gravity>
      <visual name='visual'>
        <pose>0 0.09 0 -1.5707 -0 -1.5707</pose>
        <geometry>
          <mesh>
            <scale>0.001 0.001 0.001</scale>
            <uri>model://robot/meshes/MARVIC-GNR2.stl</uri>
          </mesh>
        </geometry>
        <material>
          <lighting>1</lighting>
          <script>
            <uri>file://media/materials/scripts/gazebo.material</uri>
            <name>Gazebo/Grey</name>
          </script>
          <shader type='pixel'>
            <normal_map>__default__</normal_map>
          </shader>
          <ambient>0.3 0.8 0.3 1</ambient>
          <diffuse>0.5 0.6 0.5 1</diffuse>
          <specular>0.01 0.01 0.01 1</specular>
          <emissive>0 0 0 1</emissive>
        </material>
        <transparency>0</transparency>
        <cast_shadows>1</cast_shadows>
      </visual>

      <collision name='collision'>
        <laser_retro>0</laser_retro>
        <max_contacts>10</max_contacts>
        <pose>0 0 0 0 -0 0</pose>
        <geometry>
          <box>
            <size>0.6 0.4 0.3</size>
          </box>
        </geometry>
      </collision>
    </link>
    
    <link name="camera_link">
      <pose>0.3 0 0 0 0 0  </pose>
      
      <!-- <collision name="collision">
          <geometry>
            <cylinder>
              <radius>.005</radius>
              <length>.018</length>
            </cylinder>
          </geometry>
        </collision> -->
      <visual name='camera_link'>
        <pose>0 0 0 0 1.5707 0</pose>
        <geometry>
          <cylinder>
            <radius>.005</radius>
            <length>.018</length>
          </cylinder>
        </geometry>
      </visual>

      <sensor name="cam" type="camera">
        <pose>0 0 0 0 0 0</pose>
        <camera>
          <horizontal_fov>1.36136</horizontal_fov>
          <image>
            <width>640</width>
            <height>480</height>
          </image>
          <clip>
            <near>0.1</near>
            <far>1000</far>
          </clip>
        </camera>
        <always_on>1</always_on>
        <update_rate>30</update_rate>
        <visualize>true</visualize>
        <plugin name="camera_controller" filename="libgazebo_ros_camera.so">
          <always_on>true</always_on>
          <update_rate>30</update_rate>
          <cameraName>camera</cameraName>
          <imageTopicName>image_raw</imageTopicName>
          <cameraInfoTopicName>camera_info</cameraInfoTopicName>
          <frameName>camera_link</frameName>
        </plugin>
      </sensor>
    </link>

    <joint name="camera_joint" type="revolute">
      <pose>0 0 0 0 0 0</pose>
      <parent>link</parent>
      <child>camera_link</child>
      <axis>
        <xyz>0 1 0</xyz>
        <limit>
          <upper>1.5707</upper>
          <lower>-1.5707</lower>
        </limit>
        <friction>0.3</friction>
        <spring_reference>0</spring_reference>
        <spring_stiffness>0.3</spring_stiffness>
      </axis>
    </joint>
    <static>0</static>
    <allow_auto_disable>1</allow_auto_disable>
  </model>
</sdf>